2022-02-12 02:20:19,330 INFO    MainThread:805 [internal.py:wandb_internal():91] W&B internal server running at pid: 805, started at: 2022-02-12 02:20:19.330094
2022-02-12 02:20:19,334 INFO    WriterThread:805 [datastore.py:open_for_write():77] open: /workspace/Hieu/graph-neural-pde/src/wandb/run-20220212_022018-Clipped alpha = 2 bound = 0.3 T = 128/run-Clipped alpha = 2 bound = 0.3 T = 128.wandb
2022-02-12 02:20:19,336 DEBUG   HandlerThread:805 [handler.py:handle_request():120] handle_request: check_version
2022-02-12 02:20:19,337 DEBUG   SenderThread:805 [sender.py:send():160] send: header
2022-02-12 02:20:19,337 DEBUG   SenderThread:805 [sender.py:send():160] send: request
2022-02-12 02:20:19,337 DEBUG   SenderThread:805 [sender.py:send_request():169] send_request: check_version
2022-02-12 02:20:19,573 DEBUG   SenderThread:805 [sender.py:send():160] send: run
2022-02-12 02:20:19,966 ERROR   SenderThread:805 [internal_api.py:execute():127] 409 response executing GraphQL.
2022-02-12 02:20:19,967 ERROR   SenderThread:805 [internal_api.py:execute():128] {"errors":[{"message":"Error 1062: Duplicate entry '701428-Clipped alpha = 2 bound = 0.3 T = 128' for key 'PRIMARY'","path":["upsertBucket"]}],"data":{"upsertBucket":null}}
2022-02-12 02:20:21,471 ERROR   SenderThread:805 [internal_api.py:execute():127] 409 response executing GraphQL.
2022-02-12 02:20:21,471 ERROR   SenderThread:805 [internal_api.py:execute():128] {"errors":[{"message":"Error 1062: Duplicate entry '701428-Clipped alpha = 2 bound = 0.3 T = 128' for key 'PRIMARY'","path":["upsertBucket"]}],"data":{"upsertBucket":null}}
2022-02-12 02:20:23,902 ERROR   SenderThread:805 [internal_api.py:execute():127] 409 response executing GraphQL.
2022-02-12 02:20:23,903 ERROR   SenderThread:805 [internal_api.py:execute():128] {"errors":[{"message":"Error 1062: Duplicate entry '701428-Clipped alpha = 2 bound = 0.3 T = 128' for key 'PRIMARY'","path":["upsertBucket"]}],"data":{"upsertBucket":null}}
2022-02-12 02:20:23,903 ERROR   SenderThread:805 [retry.py:__call__():111] Retry attempt failed:
Traceback (most recent call last):
  File "/opt/conda/lib/python3.6/site-packages/wandb/old/retry.py", line 96, in __call__
    result = self._call_fn(*args, **kwargs)
  File "/opt/conda/lib/python3.6/site-packages/wandb/sdk/internal/internal_api.py", line 130, in execute
    six.reraise(*sys.exc_info())
  File "/opt/conda/lib/python3.6/site-packages/six.py", line 703, in reraise
    raise value
  File "/opt/conda/lib/python3.6/site-packages/wandb/sdk/internal/internal_api.py", line 124, in execute
    return self.client.execute(*args, **kwargs)
  File "/opt/conda/lib/python3.6/site-packages/wandb/vendor/gql-0.2.0/gql/client.py", line 52, in execute
    result = self._get_result(document, *args, **kwargs)
  File "/opt/conda/lib/python3.6/site-packages/wandb/vendor/gql-0.2.0/gql/client.py", line 60, in _get_result
    return self.transport.execute(document, *args, **kwargs)
  File "/opt/conda/lib/python3.6/site-packages/wandb/vendor/gql-0.2.0/gql/transport/requests.py", line 39, in execute
    request.raise_for_status()
  File "/opt/conda/lib/python3.6/site-packages/requests/models.py", line 941, in raise_for_status
    raise HTTPError(http_error_msg, response=self)
requests.exceptions.HTTPError: 409 Client Error: Conflict for url: https://api.wandb.ai/graphql
2022-02-12 02:20:28,844 ERROR   SenderThread:805 [internal_api.py:execute():127] 409 response executing GraphQL.
2022-02-12 02:20:28,844 ERROR   SenderThread:805 [internal_api.py:execute():128] {"errors":[{"message":"Error 1062: Duplicate entry '701428-Clipped alpha = 2 bound = 0.3 T = 128' for key 'PRIMARY'","path":["upsertBucket"]}],"data":{"upsertBucket":null}}
2022-02-12 02:20:38,219 ERROR   SenderThread:805 [internal_api.py:execute():127] 409 response executing GraphQL.
2022-02-12 02:20:38,220 ERROR   SenderThread:805 [internal_api.py:execute():128] {"errors":[{"message":"Error 1062: Duplicate entry '701428-Clipped alpha = 2 bound = 0.3 T = 128' for key 'PRIMARY'","path":["upsertBucket"]}],"data":{"upsertBucket":null}}
2022-02-12 02:20:39,995 WARNING MainThread:805 [internal.py:wandb_internal():146] Internal process interrupt: 1
2022-02-12 02:20:46,976 WARNING MainThread:805 [internal.py:wandb_internal():146] Internal process interrupt: 2
2022-02-12 02:20:46,976 ERROR   MainThread:805 [internal.py:wandb_internal():149] Internal process interrupted.
2022-02-12 02:20:47,579 INFO    WriterThread:805 [datastore.py:close():258] close: /workspace/Hieu/graph-neural-pde/src/wandb/run-20220212_022018-Clipped alpha = 2 bound = 0.3 T = 128/run-Clipped alpha = 2 bound = 0.3 T = 128.wandb
2022-02-12 02:20:47,606 INFO    HandlerThread:805 [handler.py:finish():624] shutting down handler
2022-02-12 02:20:56,663 ERROR   SenderThread:805 [internal_api.py:execute():127] 409 response executing GraphQL.
2022-02-12 02:20:56,663 ERROR   SenderThread:805 [internal_api.py:execute():128] {"errors":[{"message":"Error 1062: Duplicate entry '701428-Clipped alpha = 2 bound = 0.3 T = 128' for key 'PRIMARY'","path":["upsertBucket"]}],"data":{"upsertBucket":null}}
2022-02-12 02:21:35,808 ERROR   SenderThread:805 [internal_api.py:execute():127] 409 response executing GraphQL.
2022-02-12 02:21:35,808 ERROR   SenderThread:805 [internal_api.py:execute():128] {"errors":[{"message":"Error 1062: Duplicate entry '701428-Clipped alpha = 2 bound = 0.3 T = 128' for key 'PRIMARY'","path":["upsertBucket"]}],"data":{"upsertBucket":null}}
2022-02-12 02:22:50,338 ERROR   SenderThread:805 [internal_api.py:execute():127] 409 response executing GraphQL.
2022-02-12 02:22:50,339 ERROR   SenderThread:805 [internal_api.py:execute():128] {"errors":[{"message":"Error 1062: Duplicate entry '701428-Clipped alpha = 2 bound = 0.3 T = 128' for key 'PRIMARY'","path":["upsertBucket"]}],"data":{"upsertBucket":null}}
2022-02-12 02:22:50,339 ERROR   MainThread:805 [internal.py:wandb_internal():158] Thread SenderThread:
Traceback (most recent call last):
  File "/opt/conda/lib/python3.6/site-packages/wandb/sdk/internal/internal_api.py", line 124, in execute
    return self.client.execute(*args, **kwargs)
  File "/opt/conda/lib/python3.6/site-packages/wandb/vendor/gql-0.2.0/gql/client.py", line 52, in execute
    result = self._get_result(document, *args, **kwargs)
  File "/opt/conda/lib/python3.6/site-packages/wandb/vendor/gql-0.2.0/gql/client.py", line 60, in _get_result
    return self.transport.execute(document, *args, **kwargs)
  File "/opt/conda/lib/python3.6/site-packages/wandb/vendor/gql-0.2.0/gql/transport/requests.py", line 39, in execute
    request.raise_for_status()
  File "/opt/conda/lib/python3.6/site-packages/requests/models.py", line 941, in raise_for_status
    raise HTTPError(http_error_msg, response=self)
requests.exceptions.HTTPError: 409 Client Error: Conflict for url: https://api.wandb.ai/graphql

During handling of the above exception, another exception occurred:

Traceback (most recent call last):
  File "/opt/conda/lib/python3.6/site-packages/wandb/apis/normalize.py", line 24, in wrapper
    return func(*args, **kwargs)
  File "/opt/conda/lib/python3.6/site-packages/wandb/sdk/internal/internal_api.py", line 886, in upsert_run
    response = self.gql(mutation, variable_values=variable_values, **kwargs)
  File "/opt/conda/lib/python3.6/site-packages/wandb/old/retry.py", line 96, in __call__
    result = self._call_fn(*args, **kwargs)
  File "/opt/conda/lib/python3.6/site-packages/wandb/sdk/internal/internal_api.py", line 129, in execute
    self.display_gorilla_error_if_found(res)
  File "/opt/conda/lib/python3.6/site-packages/wandb/sdk/internal/internal_api.py", line 146, in display_gorilla_error_if_found
    "Error while calling W&B API: {} ({})".format(err["message"], res)
  File "/opt/conda/lib/python3.6/site-packages/wandb/errors/term.py", line 63, in termerror
    **kwargs
  File "/opt/conda/lib/python3.6/site-packages/wandb/errors/term.py", line 94, in _log
    click.echo(line, file=sys.stderr, nl=newline)
  File "/opt/conda/lib/python3.6/site-packages/click/utils.py", line 272, in echo
    file.write(message)
OSError: [Errno 5] Input/output error

During handling of the above exception, another exception occurred:

Traceback (most recent call last):
  File "/opt/conda/lib/python3.6/site-packages/wandb/sdk/internal/internal_util.py", line 54, in run
    self._run()
  File "/opt/conda/lib/python3.6/site-packages/wandb/sdk/internal/internal_util.py", line 95, in _run
    self._process(record)
  File "/opt/conda/lib/python3.6/site-packages/wandb/sdk/internal/internal.py", line 279, in _process
    self._sm.send(record)
  File "/opt/conda/lib/python3.6/site-packages/wandb/sdk/internal/sender.py", line 162, in send
    send_handler(record)
  File "/opt/conda/lib/python3.6/site-packages/wandb/sdk/internal/sender.py", line 541, in send_run
    self._init_run(run, config_value_dict)
  File "/opt/conda/lib/python3.6/site-packages/wandb/sdk/internal/sender.py", line 577, in _init_run
    commit=repo.last_commit,
  File "/opt/conda/lib/python3.6/site-packages/wandb/apis/normalize.py", line 62, in wrapper
    six.reraise(CommError, CommError(message, err), sys.exc_info()[2])
  File "/opt/conda/lib/python3.6/site-packages/six.py", line 702, in reraise
    raise value.with_traceback(tb)
  File "/opt/conda/lib/python3.6/site-packages/wandb/apis/normalize.py", line 24, in wrapper
    return func(*args, **kwargs)
  File "/opt/conda/lib/python3.6/site-packages/wandb/sdk/internal/internal_api.py", line 886, in upsert_run
    response = self.gql(mutation, variable_values=variable_values, **kwargs)
  File "/opt/conda/lib/python3.6/site-packages/wandb/old/retry.py", line 96, in __call__
    result = self._call_fn(*args, **kwargs)
  File "/opt/conda/lib/python3.6/site-packages/wandb/sdk/internal/internal_api.py", line 129, in execute
    self.display_gorilla_error_if_found(res)
  File "/opt/conda/lib/python3.6/site-packages/wandb/sdk/internal/internal_api.py", line 146, in display_gorilla_error_if_found
    "Error while calling W&B API: {} ({})".format(err["message"], res)
  File "/opt/conda/lib/python3.6/site-packages/wandb/errors/term.py", line 63, in termerror
    **kwargs
  File "/opt/conda/lib/python3.6/site-packages/wandb/errors/term.py", line 94, in _log
    click.echo(line, file=sys.stderr, nl=newline)
  File "/opt/conda/lib/python3.6/site-packages/click/utils.py", line 272, in echo
    file.write(message)
wandb.errors.CommError: [Errno 5] Input/output error
2022-02-12 02:22:50,361 INFO    MainThread:805 [internal.py:handle_exit():78] Internal process exited
