2022-01-27 06:41:11,153 INFO    MainThread:494 [internal.py:wandb_internal():91] W&B internal server running at pid: 494, started at: 2022-01-27 06:41:11.153668
2022-01-27 06:41:11,155 INFO    WriterThread:494 [datastore.py:open_for_write():77] open: /workspace/graph-neural-pde/src/wandb/run-20220127_064110-grandpp-alpha:1.0-T:0.1/run-grandpp-alpha:1.0-T:0.1.wandb
2022-01-27 06:41:11,155 DEBUG   HandlerThread:494 [handler.py:handle_request():120] handle_request: check_version
2022-01-27 06:41:11,156 DEBUG   SenderThread:494 [sender.py:send():160] send: header
2022-01-27 06:41:11,156 DEBUG   SenderThread:494 [sender.py:send():160] send: request
2022-01-27 06:41:11,156 DEBUG   SenderThread:494 [sender.py:send_request():169] send_request: check_version
2022-01-27 06:41:11,359 DEBUG   SenderThread:494 [sender.py:send():160] send: run
2022-01-27 06:41:11,874 ERROR   SenderThread:494 [internal_api.py:execute():127] 400 response executing GraphQL.
2022-01-27 06:41:11,875 ERROR   SenderThread:494 [internal_api.py:execute():128] {"errors":[{"message":"invalid run name grandpp-alpha:1.0-T:0.1, cannot contain character \":\"","path":["upsertBucket"]}],"data":{"upsertBucket":null}}
2022-01-27 06:41:12,360 INFO    HandlerThread:494 [handler.py:finish():624] shutting down handler
2022-01-27 06:41:12,365 INFO    WriterThread:494 [datastore.py:close():258] close: /workspace/graph-neural-pde/src/wandb/run-20220127_064110-grandpp-alpha:1.0-T:0.1/run-grandpp-alpha:1.0-T:0.1.wandb
2022-01-27 06:41:12,365 ERROR   MainThread:494 [internal.py:wandb_internal():158] Thread SenderThread:
Traceback (most recent call last):
  File "/opt/conda/lib/python3.6/site-packages/wandb/apis/normalize.py", line 24, in wrapper
    return func(*args, **kwargs)
  File "/opt/conda/lib/python3.6/site-packages/wandb/sdk/internal/internal_api.py", line 886, in upsert_run
    response = self.gql(mutation, variable_values=variable_values, **kwargs)
  File "/opt/conda/lib/python3.6/site-packages/wandb/old/retry.py", line 96, in __call__
    result = self._call_fn(*args, **kwargs)
  File "/opt/conda/lib/python3.6/site-packages/wandb/sdk/internal/internal_api.py", line 130, in execute
    six.reraise(*sys.exc_info())
  File "/opt/conda/lib/python3.6/site-packages/six.py", line 703, in reraise
    raise value
  File "/opt/conda/lib/python3.6/site-packages/wandb/sdk/internal/internal_api.py", line 124, in execute
    return self.client.execute(*args, **kwargs)
  File "/opt/conda/lib/python3.6/site-packages/wandb/vendor/gql-0.2.0/gql/client.py", line 52, in execute
    result = self._get_result(document, *args, **kwargs)
  File "/opt/conda/lib/python3.6/site-packages/wandb/vendor/gql-0.2.0/gql/client.py", line 60, in _get_result
    return self.transport.execute(document, *args, **kwargs)
  File "/opt/conda/lib/python3.6/site-packages/wandb/vendor/gql-0.2.0/gql/transport/requests.py", line 39, in execute
    request.raise_for_status()
  File "/opt/conda/lib/python3.6/site-packages/requests/models.py", line 941, in raise_for_status
    raise HTTPError(http_error_msg, response=self)
requests.exceptions.HTTPError: 400 Client Error: Bad Request for url: https://api.wandb.ai/graphql

During handling of the above exception, another exception occurred:

Traceback (most recent call last):
  File "/opt/conda/lib/python3.6/site-packages/wandb/sdk/internal/internal_util.py", line 54, in run
    self._run()
  File "/opt/conda/lib/python3.6/site-packages/wandb/sdk/internal/internal_util.py", line 95, in _run
    self._process(record)
  File "/opt/conda/lib/python3.6/site-packages/wandb/sdk/internal/internal.py", line 279, in _process
    self._sm.send(record)
  File "/opt/conda/lib/python3.6/site-packages/wandb/sdk/internal/sender.py", line 162, in send
    send_handler(record)
  File "/opt/conda/lib/python3.6/site-packages/wandb/sdk/internal/sender.py", line 541, in send_run
    self._init_run(run, config_value_dict)
  File "/opt/conda/lib/python3.6/site-packages/wandb/sdk/internal/sender.py", line 577, in _init_run
    commit=repo.last_commit,
  File "/opt/conda/lib/python3.6/site-packages/wandb/apis/normalize.py", line 26, in wrapper
    raise CommError(err.response, err)
wandb.errors.CommError: <Response [400]>
2022-01-27 06:41:14,394 INFO    MainThread:494 [internal.py:handle_exit():78] Internal process exited
