2022-01-27 06:44:09,433 INFO    MainThread:2478 [internal.py:wandb_internal():91] W&B internal server running at pid: 2478, started at: 2022-01-27 06:44:09.433388
2022-01-27 06:44:09,434 DEBUG   HandlerThread:2478 [handler.py:handle_request():120] handle_request: check_version
2022-01-27 06:44:09,435 INFO    WriterThread:2478 [datastore.py:open_for_write():77] open: /workspace/graph-neural-pde/src/wandb/run-20220127_064408-grandpp-alpha=1.0-T=0.1/run-grandpp-alpha=1.0-T=0.1.wandb
2022-01-27 06:44:09,436 DEBUG   SenderThread:2478 [sender.py:send():160] send: header
2022-01-27 06:44:09,436 DEBUG   SenderThread:2478 [sender.py:send():160] send: request
2022-01-27 06:44:09,436 DEBUG   SenderThread:2478 [sender.py:send_request():169] send_request: check_version
2022-01-27 06:44:09,674 DEBUG   SenderThread:2478 [sender.py:send():160] send: run
2022-01-27 06:44:10,140 ERROR   SenderThread:2478 [internal_api.py:execute():127] 409 response executing GraphQL.
2022-01-27 06:44:10,141 ERROR   SenderThread:2478 [internal_api.py:execute():128] {"errors":[{"message":"Error 1062: Duplicate entry '644113-grandpp-alpha=1.0-T=0.1' for key 'PRIMARY'","path":["upsertBucket"]}],"data":{"upsertBucket":null}}
2022-01-27 06:44:11,618 ERROR   SenderThread:2478 [internal_api.py:execute():127] 409 response executing GraphQL.
2022-01-27 06:44:11,619 ERROR   SenderThread:2478 [internal_api.py:execute():128] {"errors":[{"message":"Error 1062: Duplicate entry '644113-grandpp-alpha=1.0-T=0.1' for key 'PRIMARY'","path":["upsertBucket"]}],"data":{"upsertBucket":null}}
2022-01-27 06:44:14,447 ERROR   SenderThread:2478 [internal_api.py:execute():127] 409 response executing GraphQL.
2022-01-27 06:44:14,448 ERROR   SenderThread:2478 [internal_api.py:execute():128] {"errors":[{"message":"Error 1062: Duplicate entry '644113-grandpp-alpha=1.0-T=0.1' for key 'PRIMARY'","path":["upsertBucket"]}],"data":{"upsertBucket":null}}
2022-01-27 06:44:14,448 ERROR   SenderThread:2478 [retry.py:__call__():111] Retry attempt failed:
Traceback (most recent call last):
  File "/opt/conda/lib/python3.6/site-packages/wandb/old/retry.py", line 96, in __call__
    result = self._call_fn(*args, **kwargs)
  File "/opt/conda/lib/python3.6/site-packages/wandb/sdk/internal/internal_api.py", line 130, in execute
    six.reraise(*sys.exc_info())
  File "/opt/conda/lib/python3.6/site-packages/six.py", line 703, in reraise
    raise value
  File "/opt/conda/lib/python3.6/site-packages/wandb/sdk/internal/internal_api.py", line 124, in execute
    return self.client.execute(*args, **kwargs)
  File "/opt/conda/lib/python3.6/site-packages/wandb/vendor/gql-0.2.0/gql/client.py", line 52, in execute
    result = self._get_result(document, *args, **kwargs)
  File "/opt/conda/lib/python3.6/site-packages/wandb/vendor/gql-0.2.0/gql/client.py", line 60, in _get_result
    return self.transport.execute(document, *args, **kwargs)
  File "/opt/conda/lib/python3.6/site-packages/wandb/vendor/gql-0.2.0/gql/transport/requests.py", line 39, in execute
    request.raise_for_status()
  File "/opt/conda/lib/python3.6/site-packages/requests/models.py", line 941, in raise_for_status
    raise HTTPError(http_error_msg, response=self)
requests.exceptions.HTTPError: 409 Client Error: Conflict for url: https://api.wandb.ai/graphql
2022-01-27 06:44:16,880 WARNING MainThread:2478 [internal.py:wandb_internal():146] Internal process interrupt: 1
2022-01-27 06:44:18,558 WARNING MainThread:2478 [internal.py:wandb_internal():146] Internal process interrupt: 2
2022-01-27 06:44:18,558 ERROR   MainThread:2478 [internal.py:wandb_internal():149] Internal process interrupted.
2022-01-27 06:44:18,676 INFO    WriterThread:2478 [datastore.py:close():258] close: /workspace/graph-neural-pde/src/wandb/run-20220127_064408-grandpp-alpha=1.0-T=0.1/run-grandpp-alpha=1.0-T=0.1.wandb
2022-01-27 06:44:18,685 INFO    HandlerThread:2478 [handler.py:finish():624] shutting down handler
2022-01-27 06:44:18,901 ERROR   SenderThread:2478 [internal_api.py:execute():127] 409 response executing GraphQL.
2022-01-27 06:44:18,901 ERROR   SenderThread:2478 [internal_api.py:execute():128] {"errors":[{"message":"Error 1062: Duplicate entry '644113-grandpp-alpha=1.0-T=0.1' for key 'PRIMARY'","path":["upsertBucket"]}],"data":{"upsertBucket":null}}
2022-01-27 06:44:27,523 ERROR   SenderThread:2478 [internal_api.py:execute():127] 409 response executing GraphQL.
2022-01-27 06:44:27,524 ERROR   SenderThread:2478 [internal_api.py:execute():128] {"errors":[{"message":"Error 1062: Duplicate entry '644113-grandpp-alpha=1.0-T=0.1' for key 'PRIMARY'","path":["upsertBucket"]}],"data":{"upsertBucket":null}}
2022-01-27 06:44:44,461 ERROR   SenderThread:2478 [internal_api.py:execute():127] 409 response executing GraphQL.
2022-01-27 06:44:44,462 ERROR   SenderThread:2478 [internal_api.py:execute():128] {"errors":[{"message":"Error 1062: Duplicate entry '644113-grandpp-alpha=1.0-T=0.1' for key 'PRIMARY'","path":["upsertBucket"]}],"data":{"upsertBucket":null}}
2022-01-27 06:45:21,900 ERROR   SenderThread:2478 [internal_api.py:execute():127] 409 response executing GraphQL.
2022-01-27 06:45:21,901 ERROR   SenderThread:2478 [internal_api.py:execute():128] {"errors":[{"message":"Error 1062: Duplicate entry '644113-grandpp-alpha=1.0-T=0.1' for key 'PRIMARY'","path":["upsertBucket"]}],"data":{"upsertBucket":null}}
2022-01-27 06:46:39,857 ERROR   SenderThread:2478 [internal_api.py:execute():127] 409 response executing GraphQL.
2022-01-27 06:46:39,857 ERROR   SenderThread:2478 [internal_api.py:execute():128] {"errors":[{"message":"Error 1062: Duplicate entry '644113-grandpp-alpha=1.0-T=0.1' for key 'PRIMARY'","path":["upsertBucket"]}],"data":{"upsertBucket":null}}
